<?xml version="1.0"?>
<robot name="XML">

<!-- material color setting -->
<material name="#ffffff">
  <color rgba="1.000 1.000 1.000 1.0"/>
</material>

  <link name="base_link"/>

  <joint name="base_link_to_base_link_sub" type="fixed">
    <origin xyz="0 0 0" rpy="0.0 0.0 0.0"/>
    <parent link="base_link"/>
    <child link="base_link_sub"/>
  </joint>

  <link name="base_link_sub">
    <inertial>
      <origin xyz="0.0 0.0 0.0" rpy="0.0 0.0 0.0"/>
      <mass value="0"/>
      <inertia ixx="0" ixy="0" ixz="0" iyy="0" iyz="0" izz="0"/>
    </inertial>
  </link>

  <joint name="base_link_sub_to_Frame only STL" type="revolute">
    <origin xyz="0.0 0.0 0.0" rpy="0.0 0.0 0.0"/>
    <axis xyz="0 1 0"/>
    <parent link="base_link_sub"/>
    <child link="Frame only STL"/>
    <limit lower="-3.14159" upper="3.14159" effort="1.37" velocity="7.0"/>
    <dynamics damping="0.18" friction="0.005"/>
  </joint>
  <gazebo reference="base_link_sub_to_Frame only STL">
    <implicitSpringDamper>true</implicitSpringDamper>
    <springStiffness>100</springStiffness>
    <springReference>0.0</springReference>
  </gazebo>

  <link name="Frame only STL">
    <inertial>
      <origin xyz="0.38972 -95.362751 0.334853" rpy="0.0 0.0 0.0"/>
      <mass value="11328708.201834924519062"/>
      <inertia ixx="1128857633645.655517578125" ixy="-294938608.16349458694458" ixz="-49121238.767162702977657" iyy="1440582021221.099365234375" iyz="-108383105.360172227025032" izz="963864822594.31494140625"/>
    </inertial>
    <visual>
      <origin xyz="0 0 0" rpy="0 0 0"/>
      <geometry>
        <mesh filename="package://XML_description/meshes/Frame only STL.stl"/>
      </geometry>
      <material name="#ffffff"/>
    </visual>
    <collision>
      <origin xyz="0.0 -222.4148 0.0" rpy="0.0 0.0 0.0"/>
      <geometry>
        <box size="1060.5326 603.5296 1149.8845"/>
      </geometry>
    </collision>
  </link>

  <joint name="Frame only STL_to_BR 1" type="revolute">
    <origin xyz="468.0 48.0 -515.39" rpy="0.0 0.0 0.0"/>
    <axis xyz="1 0 0"/>
    <parent link="Frame only STL"/>
    <child link="BR 1"/>
    <limit lower="-3.14159" upper="3.14159" effort="1.37" velocity="7.0"/>
    <dynamics damping="0.18" friction="0.005"/>
  </joint>
  <gazebo reference="Frame only STL_to_BR 1">
    <implicitSpringDamper>true</implicitSpringDamper>
    <springStiffness>100</springStiffness>
    <springReference>0.0</springReference>
  </gazebo>

  <link name="BR 1">
    <inertial>
      <origin xyz="-0.0 -1.520206 0.0" rpy="0.0 0.0 0.0"/>
      <mass value="55310.553331254413933"/>
      <inertia ixx="2133257654.298996686935425" ixy="0.00192179" ixz="66723688.658028796315193" iyy="2138430844.72761869430542" iyz="0.0056059" izz="200120878.203556567430496"/>
    </inertial>
    <visual>
      <origin xyz="0 0 0" rpy="0 0 0"/>
      <geometry>
        <mesh filename="package://XML_description/meshes/FL.stl"/>
      </geometry>
      <material name="#ffffff"/>
    </visual>
    <collision>
      <origin xyz="0.0 -4.5926 0.0" rpy="0.0 0.0 0.0"/>
      <geometry>
        <box size="64.4522 13.2286 812.8"/>
      </geometry>
    </collision>
  </link>

  <joint name="Frame only STL_to_BL 1" type="revolute">
    <origin xyz="-468.0 48.0 -515.39" rpy="0.0 0.0 0.0"/>
    <axis xyz="1 0 0"/>
    <parent link="Frame only STL"/>
    <child link="BL 1"/>
    <limit lower="-3.14159" upper="3.14159" effort="1.37" velocity="7.0"/>
    <dynamics damping="0.18" friction="0.005"/>
  </joint>
  <gazebo reference="Frame only STL_to_BL 1">
    <implicitSpringDamper>true</implicitSpringDamper>
    <springStiffness>100</springStiffness>
    <springReference>0.0</springReference>
  </gazebo>

  <link name="BL 1">
    <inertial>
      <origin xyz="-0.0 -1.520206 0.0" rpy="0.0 0.0 0.0"/>
      <mass value="55310.553331254413933"/>
      <inertia ixx="2133257654.298996686935425" ixy="0.00192179" ixz="66723688.658028796315193" iyy="2138430844.72761869430542" iyz="0.0056059" izz="200120878.203556567430496"/>
    </inertial>
    <visual>
      <origin xyz="0 0 0" rpy="0 0 0"/>
      <geometry>
        <mesh filename="package://XML_description/meshes/FR.stl"/>
      </geometry>
      <material name="#ffffff"/>
    </visual>
    <collision>
      <origin xyz="0.0 -4.5926 0.0" rpy="0.0 0.0 0.0"/>
      <geometry>
        <box size="64.4522 13.2286 812.8"/>
      </geometry>
    </collision>
  </link>

  <joint name="Frame only STL_to_BR" type="revolute">
    <origin xyz="468.0 48.0 515.39" rpy="0.0 0.0 0.0"/>
    <axis xyz="1 0 0"/>
    <parent link="Frame only STL"/>
    <child link="BR"/>
    <limit lower="-3.14159" upper="3.14159" effort="1.37" velocity="7.0"/>
    <dynamics damping="0.18" friction="0.005"/>
  </joint>
  <gazebo reference="Frame only STL_to_BR">
    <implicitSpringDamper>true</implicitSpringDamper>
    <springStiffness>100</springStiffness>
    <springReference>0.0</springReference>
  </gazebo>

  <link name="BR">
    <inertial>
      <origin xyz="-0.0 -1.520206 0.0" rpy="0.0 0.0 0.0"/>
      <mass value="55310.553331254413933"/>
      <inertia ixx="2133257654.298996686935425" ixy="0.00192179" ixz="66723688.658028796315193" iyy="2138430844.72761869430542" iyz="0.0056059" izz="200120878.203556567430496"/>
    </inertial>
    <visual>
      <origin xyz="0 0 0" rpy="0 0 0"/>
      <geometry>
        <mesh filename="package://XML_description/meshes/BR.stl"/>
      </geometry>
      <material name="#ffffff"/>
    </visual>
    <collision>
      <origin xyz="0.0 -4.5926 0.0" rpy="0.0 0.0 0.0"/>
      <geometry>
        <box size="64.4522 13.2286 812.8"/>
      </geometry>
    </collision>
  </link>

  <joint name="Frame only STL_to_BL" type="revolute">
    <origin xyz="-468.0 48.0 515.39" rpy="0.0 0.0 0.0"/>
    <axis xyz="1 0 0"/>
    <parent link="Frame only STL"/>
    <child link="BL"/>
    <limit lower="-3.14159" upper="3.14159" effort="1.37" velocity="7.0"/>
    <dynamics damping="0.18" friction="0.005"/>
  </joint>
  <gazebo reference="Frame only STL_to_BL">
    <implicitSpringDamper>true</implicitSpringDamper>
    <springStiffness>100</springStiffness>
    <springReference>0.0</springReference>
  </gazebo>

  <link name="BL">
    <inertial>
      <origin xyz="-0.0 -1.520206 0.0" rpy="0.0 0.0 0.0"/>
      <mass value="55310.553331254413933"/>
      <inertia ixx="2133257654.298996686935425" ixy="0.00192179" ixz="66723688.658028796315193" iyy="2138430844.72761869430542" iyz="0.0056059" izz="200120878.203556567430496"/>
    </inertial>
    <visual>
      <origin xyz="0 0 0" rpy="0 0 0"/>
      <geometry>
        <mesh filename="package://XML_description/meshes/BL.stl"/>
      </geometry>
      <material name="#ffffff"/>
    </visual>
    <collision>
      <origin xyz="0.0 -4.5926 0.0" rpy="0.0 0.0 0.0"/>
      <geometry>
        <box size="64.4522 13.2286 812.8"/>
      </geometry>
    </collision>
  </link>

</robot>
